**Coroutine Scope의 예외 처리 특징**

이번 강의에서는 **Coroutine Scope의 예외 처리 방식**에 대해 살펴보겠습니다.
이전 강의에서 배운 **구조적 동시성(Structured Concurrency)** 개념을 바탕으로,
coroutineScope와 supervisorScope의 예외 처리 방식을 비교할 것입니다.

**1. Coroutine Scope 예외 전파**

먼저 coroutineScope를 사용할 때 예외가 어떻게 전파되는지 살펴보겠습니다.

**기본적인 예제**

```kotlin
import kotlinx.coroutines.*

fun main() = runBlocking {
    try {
        coroutineScope {
            launch {
                delay(100)
                throw RuntimeException("예외 발생!")
            }
        }
    } catch (e: Exception) {
        println("예외 처리됨: ${e.message}")
    }
}
```

**출력 결과**

```
예외 처리됨: 예외 발생!
```

**✅ 설명**

• coroutineScope 내부에서 실행된 launch 블록에서 예외가 발생했습니다.
• 그런데 **이 예외는 coroutineScope에서 다시 던져지기 때문에**, **외부에서 try-catch를 사용하여 예외를 처리할 수 있습니다.**
• 즉, **coroutineScope는 예외가 발생하면 예외를 호출한 쪽으로 전파(rethrow)합니다.**

**2. runBlocking과 coroutineScope의 차이**

runBlocking과 coroutineScope의 가장 큰 차이점은 다음과 같습니다.

|**구분**|runBlocking|coroutineScope|
|---|---|---|
|**블로킹 여부**|현재 스레드를 **블로킹**|현재 스레드를 **블로킹하지 않음**|
|**예외 발생 시**|예외 발생 시 **즉시 전파됨**|예외 발생 시 **자신을 호출한 곳으로 전파됨**|
|**구조적 동시성**|부모 코루틴과 함께 종료됨|부모 코루틴과 함께 종료됨|

즉, coroutineScope는 **예외를 호출한 곳으로 전파하기 때문에** try-catch로 쉽게 처리할 수 있습니다.

**3. Coroutine Scope 내부에서 suspend 함수 사용**

coroutineScope를 사용하면, **suspend 함수 내부에서도 예외를 안전하게 처리할 수 있습니다.**

다음 예제를 통해 살펴보겠습니다.

**suspend 함수에서 예외 처리**

```kotlin
import kotlinx.coroutines.*

suspend fun performTask() {
    try {
        coroutineScope {
            launch {
                delay(100)
                throw RuntimeException("작업 중 예외 발생!")
            }
        }
    } catch (e: Exception) {
        println("예외 처리됨: ${e.message}")
    }
}

fun main() = runBlocking {
    performTask()
}
```

**출력 결과**

```
예외 처리됨: 작업 중 예외 발생!
```

**✅ 설명**

• performTask() 함수에서 coroutineScope를 사용했습니다.
• 내부의 launch에서 예외가 발생하지만, **coroutineScope가 예외를 다시 던지므로** **외부에서 try-catch로 예외를 처리할 수 있습니다.**
• 즉, coroutineScope를 사용하면 **suspend 함수 내부에서도 예외 처리를 안전하게 할 수 있습니다.**

**4. Coroutine Scope vs Supervisor Scope**

이번에는 coroutineScope와 supervisorScope의 차이를 살펴보겠습니다.

**(1) coroutineScope에서 예외 발생**

```kotlin
import kotlinx.coroutines.*

fun main() = runBlocking {
    try {
        coroutineScope {
            launch {
                delay(100)
                throw RuntimeException("launch 1 실패!")
            }
            launch {
                delay(200)
                println("launch 2 실행됨")
            }
        }
    } catch (e: Exception) {
        println("예외 처리됨: ${e.message}")
    }
}
```

**출력 결과**

```
예외 처리됨: launch 1 실패!
```

**❌ 문제점**

• launch 1에서 예외가 발생하면, **전체 coroutineScope가 종료되면서 launch 2도 취소됩니다.**
• 즉, **한 개의 코루틴에서 예외가 발생하면, 다른 모든 코루틴도 취소됩니다.**

**(2) supervisorScope에서 예외 발생**

```kotlin
import kotlinx.coroutines.*

fun main() = runBlocking {
    try {
        supervisorScope {
            launch {
                delay(100)
                throw RuntimeException("launch 1 실패!")
            }
            launch {
                delay(200)
                println("launch 2 실행됨")
            }
        }
    } catch (e: Exception) {
        println("예외 처리됨: ${e.message}")
    }
}
```

**출력 결과**

```
launch 2 실행됨
예외 처리됨: launch 1 실패!
```

**✅ 설명**

• supervisorScope를 사용하면, **launch 1에서 예외가 발생해도 launch 2는 정상적으로 실행됩니다.**
• 즉, **supervisorScope는 하나의 코루틴이 실패하더라도, 다른 코루틴이 취소되지 않습니다.**
• 따라서 **독립적인 작업을 실행해야 하는 경우 supervisorScope를 사용하는 것이 좋습니다.**

**5. 결론**

|**구분**|coroutineScope|supervisorScope|
|---|---|---|
|**예외 전파**|부모에게 전파됨|부모에게 전파되지 않음|
|**구조적 동시성**|모든 자식 코루틴이 영향을 받음|개별 코루틴이 독립적으로 실행됨|
|**사용 목적**|모든 작업이 **서로 의존적일 때**|각각의 작업이 **독립적일 때**|

**어떤 경우에 사용해야 할까?**

1. **하나의 코루틴이 실패하면 다른 코루틴도 취소해야 하는 경우**

→ coroutineScope 사용

2. **하나의 코루틴이 실패하더라도 다른 코루틴이 정상적으로 실행되어야 하는 경우**

→ supervisorScope 사용

**6. 최종 정리**

• coroutineScope는 내부에서 예외가 발생하면 **부모에게 예외를 다시 던진다.**
→ try-catch로 예외 처리가 가능하다.
• coroutineScope 내부에서 **하나의 코루틴이 실패하면, 전체가 취소된다.**
• supervisorScope는 하나의 코루틴이 실패해도, 다른 코루틴이 계속 실행된다.

• **구조적 동시성을 유지해야 하는 경우 coroutineScope, 독립적인 실행이 필요할 경우 supervisorScope 사용!** 🚀