**Coroutine 예외 처리: Try-Catch vs. Coroutine Exception Handler 언제 사용할까?**

Kotlin의 코루틴에서 예외를 처리하는 방법에는 두 가지가 있습니다.

1. **Try-Catch 블록**
2. **Coroutine Exception Handler**

  

이제 중요한 질문은 **언제 어떤 방법을 사용해야 하는가?** 입니다.

**1. Coroutine Exception Handler는 최후의 보루 (Last Resort)**

코틀린 공식 문서에서는 **Coroutine Exception Handler를 “최후의 보루(Last Resort)“로 사용하는 것이 적절하다**고 설명합니다.

즉, **예외를 복구(recover)하는 용도가 아니라**, 다음과 같은 목적으로 사용해야 합니다.

• 예외를 **로깅(logging)**
• **에러 메시지 표시**
• **애플리케이션 종료 또는 재시작**

**핵심 포인트**

• 예외가 발생한 코루틴은 이미 **완전히 종료된 상태**에서 Exception Handler가 호출됩니다.
• 따라서 **Coroutine Exception Handler 내부에서 예외를 복구할 수 없습니다.**

**2. Try-Catch는 예외를 복구할 때 사용**

**반면, Try-Catch는 예외를 복구(recover)할 필요가 있을 때 사용합니다.**

• 예를 들어, **특정 작업을 재시도(retry)하고 싶을 때** 사용합니다.
• 단, 예외를 Try-Catch에서 처리할 경우, **예외가 부모 Job으로 전파되지 않습니다.**
• 이는 **구조적 동시성(Structured Concurrency)**의 일부 기능이 비활성화될 수 있음을 의미합니다.

**3. 예제: Try-Catch vs. Coroutine Exception Handler 비교**

이제 Try-Catch와 Exception Handler를 적용한 두 가지 코드를 비교해 보겠습니다.

**3.1 Try-Catch 사용 예제 (예외가 부모 Job으로 전파되지 않음)**

```kotlin
import kotlinx.coroutines.*

fun main() {
    val scope = CoroutineScope(Job())

    scope.launch {
        // 첫 번째 코루틴
        launch {
            println("Coroutine 1: 시작")
            try {
                delay(100)
                throw RuntimeException("예상치 못한 예외 발생!")
            } catch (e: Exception) {
                println("Coroutine 1: 예외 처리됨 - ${e.message}")
            }
        }

        // 두 번째 코루틴
        launch {
            println("Coroutine 2: 시작")
            delay(3000)
            println("Coroutine 2: 완료")
        }
    }

    Thread.sleep(4000) // 메인 스레드 종료 방지
}
```

**출력 결과**

```
Coroutine 1: 시작
Coroutine 2: 시작
Coroutine 1: 예외 처리됨 - 예상치 못한 예외 발생!
Coroutine 2: 완료
```

**❌ 문제점**

• Coroutine 1에서 예외가 발생했지만, Try-Catch 내부에서 처리되었기 때문에 **부모 Job은 이를 감지하지 못합니다.**
• **Coroutine 2는 여전히 실행되며, 구조적 동시성이 적용되지 않습니다.**

**3.2 Coroutine Exception Handler 사용 예제 (구조적 동시성이 적용됨)**

```kotlin
import kotlinx.coroutines.*
import kotlin.coroutines.CoroutineContext

fun main() {
    // 1. Exception Handler 정의
    val exceptionHandler = CoroutineExceptionHandler { _: CoroutineContext, throwable: Throwable ->
        println("Caught exception: ${throwable.message}")
    }

    // 2. Coroutine Scope 생성 (Exception Handler 포함)
    val scope = CoroutineScope(Job() + exceptionHandler)

    scope.launch {
        // 첫 번째 코루틴
        launch {
            println("Coroutine 1: 시작")
            delay(100)
            throw RuntimeException("예상치 못한 예외 발생!")
        }

        // 두 번째 코루틴
        launch {
            println("Coroutine 2: 시작")
            delay(3000)
            println("Coroutine 2: 완료") // 실행되지 않음
        }
    }

    Thread.sleep(4000) // 메인 스레드 종료 방지
}
```

**출력 결과**

```
Coroutine 1: 시작
Coroutine 2: 시작
Caught exception: 예상치 못한 예외 발생!
```

**✅ 개선점**

• Coroutine 1에서 예외가 발생하면, **Coroutine Exception Handler가 호출되고, 부모 Job이 이를 감지합니다.**
• **구조적 동시성(Structured Concurrency)이 적용되어 Coroutine 2도 함께 취소됩니다.**

**4. Try-Catch와 Coroutine Exception Handler의 차이점 정리**

|**구분**|**Try-Catch**|**Coroutine Exception Handler**|
|---|---|---|
|**용도**|예외 복구 및 재시도|예외 로깅 및 앱 종료/재시작|
|**예외가 부모 Job으로 전파되는가?**|❌ 전파되지 않음|✅ 전파됨|
|**구조적 동시성 유지 여부**|❌ 유지되지 않음|✅ 유지됨|
|**사용 사례**|재시도, 예외 처리 후 정상 진행|예외 로깅, 전체 코루틴 취소|

**5. 결론**

1. **예외를 복구(recover)하고 싶다면 Try-Catch를 사용하세요.**
	• 예를 들어, **재시도(Retry) 로직이 필요할 때** Try-Catch를 활용하세요.
	• 하지만 Try-Catch를 사용하면 예외가 부모 Job으로 전파되지 않으며, 구조적 동시성이 깨질 수 있습니다.

2. **구조적 동시성을 유지하면서 예외를 처리하고 싶다면 Coroutine Exception Handler를 사용하세요.**
	• 예외를 **복구할 필요 없이 로깅(logging) 또는 앱 종료/재시작**이 필요할 때 Exception Handler를 활용하세요.
	• **부모 Job이 예외를 감지하고, 전체 코루틴이 취소될 수 있도록 보장합니다.**

이제 상황에 맞게 Try-Catch와 Coroutine Exception Handler를 적절히 활용해 보세요! 🚀


#### 추가

구조적 동시성은 다음 상황에서 필수적입니다:

1. **병렬 작업 조율**: 여러 비동기 작업을 동시에 실행하고 결과를 기다릴 때.
2. **생명주기 제한**: 코루틴이 특정 범위(예: UI, 요청) 내에서만 실행되도록.
3. **예외 관리**: 하위 작업의 실패가 상위 작업에 영향을 미쳐야 할 때.
4. **리소스 정리**: 작업이 부모 범위를 벗어나지 않도록 보장.