**Launch vs. Async: 코루틴 예외 처리 차이점**

이전까지 우리는 launch 코루틴 빌더를 사용하여 예외 처리를 다뤘습니다.
이번에는 async 코루틴 빌더에서의 예외 처리를 살펴보겠습니다.

  

두 빌더는 예외 처리 방식이 다릅니다.

즉, launch는 예외가 발생하면 즉시 **전파(propagate)** 되지만,
async는 예외를 **보류(suspend)**하고, 결과를 가져올 때 예외가 발생합니다.

**1. launch에서의 예외 처리**

먼저, launch를 사용한 기본 예제를 살펴보겠습니다.

```kotlin
import kotlinx.coroutines.*

fun main() {
    val scope = CoroutineScope(Job())

    scope.launch {
        delay(100)
        throw RuntimeException("예외 발생!")
    }

    Thread.sleep(1000) // JVM 종료 방지
}
```

**출력 결과**

```
Exception in thread "DefaultDispatcher-worker-1" java.lang.RuntimeException: 예외 발생!
	at MainKt$main$1$1.invokeSuspend(Main.kt:8)
```

**✅ 설명**

• launch를 사용하면 예외가 **즉시 전파**되며, 부모 Job이 이를 감지합니다.
• **코루틴 예외 처리기가 없다면, 예외는 JVM의 기본 uncaught exception handler로 전달됩니다.**
• 즉, 콘솔에 예외 로그가 바로 출력됩니다.

**2. async에서의 예외 처리**

이번에는 launch를 async로 변경해 보겠습니다.

```kotlin
import kotlinx.coroutines.*

fun main() {
    val scope = CoroutineScope(Job())

    scope.async {
        delay(100)
        throw RuntimeException("예외 발생!")
    }

    Thread.sleep(1000) // JVM 종료 방지
}
```

**출력 결과**

```
(아무런 출력이 없음)
```

**❌ 문제점**

• async는 **예외를 즉시 전파하지 않고, await()을 호출할 때까지 보류(suspend)합니다.**
• 위 코드에서는 await()을 호출하지 않았으므로 예외가 전파되지 않습니다.
• 따라서 JVM의 uncaught exception handler도 호출되지 않아 **콘솔에는 아무런 출력이 나타나지 않습니다.**

**3. async에서 예외를 처리하는 방법**


**방법 1: try-catch 사용**

async를 사용할 때 예외를 처리하려면 **await()을 호출하는 부분에서 try-catch를 사용해야 합니다.**

```kotlin
import kotlinx.coroutines.*

fun main() {
    val scope = CoroutineScope(Job())

    val deferred = scope.async {
        delay(100)
        throw RuntimeException("예외 발생!")
    }

    scope.launch {
        try {
            deferred.await() // 여기에서 예외가 발생함
        } catch (e: Exception) {
            println("예외 처리됨: ${e.message}")
        }
    }

    Thread.sleep(1000) // JVM 종료 방지
}
```

**출력 결과**

```
예외 처리됨: 예외 발생!
```

**✅ 설명**

• async는 await()을 호출할 때까지 예외를 보류(suspend)합니다.
• await()에서 try-catch를 사용하면 예외를 직접 처리할 수 있습니다.

**방법 2: Coroutine Exception Handler 사용 (비권장)**

기본적으로 CoroutineExceptionHandler는 launch에서만 작동합니다.
async에서 사용하려면 **launch 안에서 await()을 호출**해야 합니다.

```kotlin
import kotlinx.coroutines.*
import kotlin.coroutines.CoroutineContext

fun main() {
    val exceptionHandler = CoroutineExceptionHandler { _: CoroutineContext, throwable: Throwable ->
        println("Caught exception: ${throwable.message}")
    }

    val scope = CoroutineScope(Job() + exceptionHandler)

    val deferred = scope.async {
        delay(100)
        throw RuntimeException("예외 발생!")
    }

    scope.launch {
        try {
            deferred.await()
        } catch (e: Exception) {
            println("예외 처리됨: ${e.message}")
        }
    }

    Thread.sleep(1000)
}
```

**출력 결과**

```
예외 처리됨: 예외 발생!
```

**⚠️ 주의점**

• CoroutineExceptionHandler는 launch에서만 작동하고, async의 예외는 await()에서 직접 처리해야 합니다.
• 따라서 async에서 예외를 처리할 때는 try-catch를 사용하는 것이 일반적입니다.

**4. launch vs async 예외 처리 정리**

|**구분**|launch|async|
|---|---|---|
|**예외 발생 시점**|즉시 전파됨|await() 호출 시점까지 보류됨|
|**기본 예외 처리**|부모 Job이 감지하여 구조적 동시성 유지|await()을 호출하지 않으면 감지되지 않음|
|**추천 예외 처리 방법**|CoroutineExceptionHandler|try-catch와 await() 사용|
|**예외 전파**|부모 Job으로 전파됨|await() 호출 전에는 전파되지 않음|

**5. 결론**

1. launch는 예외가 즉시 전파되므로, **CoroutineExceptionHandler를 사용하여 예외를 처리**하는 것이 좋습니다.
2. async는 예외를 보류(suspend)하므로, **await()에서 try-catch로 예외를 직접 처리해야 합니다.**
3. async의 반환값이 필요하지 않은 경우, 굳이 async를 사용할 필요 없이 launch를 사용하는 것이 더 적절할 수 있습니다.

즉, **예외를 바로 감지하고 싶다면 launch를, 결과가 필요하고 예외를 직접 처리할 수 있다면 async를 사용하세요!** 🚀