**SupervisorScope의 예외 처리 방식**

이번 강의에서는 **supervisorScope의 예외 처리 방식**을 살펴보겠습니다.

이전 강의에서 coroutineScope를 사용하면 예외가 호출한 곳으로 전파되었지만, supervisorScope에서는 예외가 다르게 동작합니다.

**1. supervisorScope의 예외 전파 방식**

우선 coroutineScope에서 사용한 예제 코드를 supervisorScope로 변경해보겠습니다.

**(1) coroutineScope의 경우**

```kotlin
import kotlinx.coroutines.*

fun main() = runBlocking {
    try {
        coroutineScope {
            launch {
                delay(100)
                throw RuntimeException("launch 내부에서 예외 발생!")
            }
        }
    } catch (e: Exception) {
        println("예외 처리됨: ${e.message}")
    }
}
```

**출력 결과**

```
예외 처리됨: launch 내부에서 예외 발생!
```

✅ **설명**

• coroutineScope는 내부에서 예외가 발생하면 **자신을 호출한 곳으로 예외를 던집니다.**
• 따라서 try-catch를 사용하여 예외를 처리할 수 있습니다.

**(2) supervisorScope의 경우**

```kotlin
import kotlinx.coroutines.*

fun main() = runBlocking {
    try {
        supervisorScope {
            launch {
                delay(100)
                throw RuntimeException("launch 내부에서 예외 발생!")
            }
        }
    } catch (e: Exception) {
        println("예외 처리됨: ${e.message}")
    }
}
```

**출력 결과**

```
Exception in thread "main" java.lang.RuntimeException: launch 내부에서 예외 발생!
```

❌ **문제점**

• supervisorScope 내부에서 발생한 예외가 **try-catch에 의해 처리되지 않고 앱이 크래시**됩니다.

✅ **이유**

• supervisorScope는 **새로운 독립적인 스코프를 생성**합니다.
• **이 스코프 안에서 발생한 예외는 외부로 전파되지 않으며, 직접 처리해야 합니다.**

**2. supervisorScope에서 예외를 처리하는 방법**

위 문제를 해결하려면, **코루틴 내부에서 직접 예외를 처리해야 합니다.**

**(1) launch 내부에서 try-catch 사용**

```kotlin
import kotlinx.coroutines.*

fun main() = runBlocking {
    supervisorScope {
        launch {
            try {
                delay(100)
                throw RuntimeException("launch 내부에서 예외 발생!")
            } catch (e: Exception) {
                println("launch 내부에서 예외 처리됨: ${e.message}")
            }
        }
    }
}
```

**출력 결과**

```
launch 내부에서 예외 처리됨: launch 내부에서 예외 발생!
```

✅ **설명**

• launch 내부에서 직접 try-catch를 사용하여 예외를 처리하면 앱이 크래시되지 않습니다.

**(2) CoroutineExceptionHandler 사용**

또 다른 방법으로, CoroutineExceptionHandler를 사용할 수도 있습니다.

```kotlin
import kotlinx.coroutines.*

fun main() = runBlocking {
    val exceptionHandler = CoroutineExceptionHandler { _, exception ->
        println("CoroutineExceptionHandler에서 예외 처리됨: ${exception.message}")
    }

    supervisorScope {
        launch(exceptionHandler) {
            delay(100)
            throw RuntimeException("launch 내부에서 예외 발생!")
        }
    }
}
```

**출력 결과**

```
CoroutineExceptionHandler에서 예외 처리됨: launch 내부에서 예외 발생!
```

✅ **설명**

• CoroutineExceptionHandler를 사용하면, 예외가 발생했을 때 핸들러에서 처리됩니다.
• **핸들러는 최상위 코루틴에서만 동작**하며, **자식 코루틴에서는 동작하지 않습니다.**
→ 따라서 launch(exceptionHandler) {} 와 같이 **명시적으로 설정해야 합니다.**
**3. supervisorScope 내부에서 직접 예외가 발생하는 경우**

**지금까지는 launch 내부에서 예외가 발생한 경우**였습니다.

하지만 **supervisorScope 내부에서 직접 예외가 발생하는 경우**는 동작 방식이 다릅니다.

**(1) supervisorScope 내부에서 직접 예외 발생**

```kotlin
import kotlinx.coroutines.*

fun main() = runBlocking {
    try {
        supervisorScope {
            throw RuntimeException("supervisorScope 내부에서 직접 예외 발생!")
        }
    } catch (e: Exception) {
        println("예외 처리됨: ${e.message}")
    }
}
```

**출력 결과**

```
예외 처리됨: supervisorScope 내부에서 직접 예외 발생!
```

✅ **설명**

• supervisorScope 내부에서 직접 발생한 예외는 **외부의 try-catch에서 처리됩니다.**
• **자식 코루틴의 예외는 전파되지 않지만, supervisorScope 자체에서 발생한 예외는 전파됩니다.**

**4. supervisorScope 내부의 최상위 코루틴 예외 처리**

**(1) launch로 실행한 경우**

```kotlin
import kotlinx.coroutines.*

fun main() = runBlocking {
    supervisorScope {
        launch {
            delay(100)
            throw RuntimeException("launch에서 예외 발생!")
        }
    }
}
```

**출력 결과**

```
Exception in thread "main" java.lang.RuntimeException: launch에서 예외 발생!
```

❌ **문제점**

• launch를 사용하면 예외가 supervisorScope로 전파되지 않고 앱이 크래시됩니다.

**(2) async로 실행한 경우**

```kotlin
import kotlinx.coroutines.*

fun main() = runBlocking {
    supervisorScope {
        val deferred = async {
            delay(100)
            throw RuntimeException("async에서 예외 발생!")
        }
    }
}
```

**출력 결과**

```
(아무 출력 없음)
```

❌ **문제점**

• async를 사용할 경우, 예외가 발생해도 즉시 전파되지 않습니다.
• **예외는 await()를 호출할 때까지 지연됩니다.**

**(3) async + await 사용**

```kotlin
import kotlinx.coroutines.*

fun main() = runBlocking {
    try {
        supervisorScope {
            val deferred = async {
                delay(100)
                throw RuntimeException("async에서 예외 발생!")
            }
            deferred.await() // 예외가 여기서 발생
        }
    } catch (e: Exception) {
        println("예외 처리됨: ${e.message}")
    }
}
```

**출력 결과**

```
예외 처리됨: async에서 예외 발생!
```

✅ **설명**

• await()를 호출하면 async 내부에서 발생한 예외가 다시 던져집니다.
• 따라서 try-catch로 예외를 정상적으로 처리할 수 있습니다.

**5. supervisorScope에서 CoroutineExceptionHandler 적용**

이제 CoroutineExceptionHandler를 supervisorScope에서 사용해 보겠습니다.

```kotlin
import kotlinx.coroutines.*

fun main() = runBlocking {
    val exceptionHandler = CoroutineExceptionHandler { _, exception ->
        println("CoroutineExceptionHandler에서 예외 처리됨: ${exception.message}")
    }

    supervisorScope {
        launch(exceptionHandler) {
            delay(100)
            throw RuntimeException("launch에서 예외 발생!")
        }
    }
}
```

**출력 결과**

```
CoroutineExceptionHandler에서 예외 처리됨: launch에서 예외 발생!
```

✅ **설명**

• CoroutineExceptionHandler는 **최상위 코루틴(launch)에만 동작합니다.**

• **자식 코루틴에서는 동작하지 않으므로, 직접 적용해야 합니다.**

**6. 결론**

| **구분**          | coroutineScope       | supervisorScope                        |
| --------------- | -------------------- | -------------------------------------- |
| **예외 전파**       | 부모로 전파됨              | 부모로 전파되지 않음                            |
| **자식 코루틴 실패 시** | 모든 자식이 취소됨           | 다른 자식 코루틴은 계속 실행됨                      |
| **직접 예외 발생 시**  | 외부 try-catch에서 처리 가능 | 외부 try-catch에서 처리 가능                   |
| **예외 처리 방법**    | try-catch            | try-catch 또는 CoroutineExceptionHandler |

🚀 **supervisorScope 내부에서는 직접 예외 처리를 해야 한다!**